2025-03-03 14:28:08,023 INFO    StreamThr :30102 [internal.py:wandb_internal():85] W&B internal server running at pid: 30102, started at: 2025-03-03 14:28:08.017836
2025-03-03 14:28:08,039 DEBUG   HandlerThread:30102 [handler.py:handle_request():158] handle_request: status
2025-03-03 14:28:08,057 INFO    WriterThread:30102 [datastore.py:open_for_write():87] open: /share/nas2_3/adey/github/Neural-Compression-for-Radio-Astronomy/vqvae/wandb/run-20250303_142807-5fy0mcge/run-5fy0mcge.wandb
2025-03-03 14:28:08,058 DEBUG   SenderThread:30102 [sender.py:send():389] send: header
2025-03-03 14:28:08,085 DEBUG   SenderThread:30102 [sender.py:send():389] send: run
2025-03-03 14:28:08,486 INFO    SenderThread:30102 [dir_watcher.py:__init__():211] watching files in: /share/nas2_3/adey/github/Neural-Compression-for-Radio-Astronomy/vqvae/wandb/run-20250303_142807-5fy0mcge/files
2025-03-03 14:28:08,486 INFO    SenderThread:30102 [sender.py:_start_run_threads():1157] run started: 5fy0mcge with start time 1741012088.01571
2025-03-03 14:28:08,528 DEBUG   HandlerThread:30102 [handler.py:handle_request():158] handle_request: run_start
2025-03-03 14:28:08,538 DEBUG   HandlerThread:30102 [system_info.py:__init__():26] System info init
2025-03-03 14:28:08,539 DEBUG   HandlerThread:30102 [system_info.py:__init__():41] System info init done
2025-03-03 14:28:08,539 INFO    HandlerThread:30102 [system_monitor.py:start():194] Starting system monitor
2025-03-03 14:28:08,539 INFO    SystemMonitor:30102 [system_monitor.py:_start():158] Starting system asset monitoring threads
2025-03-03 14:28:08,539 INFO    HandlerThread:30102 [system_monitor.py:probe():214] Collecting system info
2025-03-03 14:28:08,564 INFO    SystemMonitor:30102 [interfaces.py:start():188] Started cpu monitoring
2025-03-03 14:28:08,567 INFO    SystemMonitor:30102 [interfaces.py:start():188] Started disk monitoring
2025-03-03 14:28:08,573 INFO    SystemMonitor:30102 [interfaces.py:start():188] Started gpu monitoring
2025-03-03 14:28:08,574 INFO    SystemMonitor:30102 [interfaces.py:start():188] Started memory monitoring
2025-03-03 14:28:08,576 INFO    SystemMonitor:30102 [interfaces.py:start():188] Started network monitoring
2025-03-03 14:28:08,577 DEBUG   HandlerThread:30102 [system_info.py:probe():152] Probing system
2025-03-03 14:28:08,616 DEBUG   HandlerThread:30102 [system_info.py:_probe_git():137] Probing git
2025-03-03 14:28:08,642 DEBUG   HandlerThread:30102 [system_info.py:_probe_git():145] Probing git done
2025-03-03 14:28:08,642 DEBUG   HandlerThread:30102 [system_info.py:probe():200] Probing system done
2025-03-03 14:28:08,642 DEBUG   HandlerThread:30102 [system_monitor.py:probe():223] {'os': 'Linux-3.10.0-693.5.2.el7.x86_64-x86_64-with-glibc2.17', 'python': '3.9.6', 'heartbeatAt': '2025-03-03T14:28:08.577273', 'startedAt': '2025-03-03T14:28:07.986230', 'docker': None, 'cuda': None, 'args': ('--n=7',), 'state': 'running', 'program': '/share/nas2_3/adey/github/Neural-Compression-for-Radio-Astronomy/vqvae/main_autoencoder_option1.py', 'codePathLocal': 'main_autoencoder_option1.py', 'codePath': 'vqvae/main_autoencoder_option1.py', 'git': {'remote': 'https://github.com/JointResearchProjectManchester/Neural-Compression-for-Radio-Astronomy.git', 'commit': '4940c66bddfae3a81ad83c69c50b815e0c09acd5'}, 'email': 'deya.03@outlook.com', 'root': '/share/nas2_3/adey/github/Neural-Compression-for-Radio-Astronomy', 'host': 'compute-0-0.local', 'username': 'adey', 'executable': '/share/nas2_3/adey/.venv/bin/python', 'cpu_count': 12, 'cpu_count_logical': 24, 'cpu_freq': {'current': 2077.7652083333332, 'min': 1200.0, 'max': 3100.0}, 'cpu_freq_per_core': [{'current': 2956.789, 'min': 1200.0, 'max': 3100.0}, {'current': 1200.062, 'min': 1200.0, 'max': 3100.0}, {'current': 3062.82, 'min': 1200.0, 'max': 3100.0}, {'current': 1207.375, 'min': 1200.0, 'max': 3100.0}, {'current': 2927.64, 'min': 1200.0, 'max': 3100.0}, {'current': 1235.812, 'min': 1200.0, 'max': 3100.0}, {'current': 2900.015, 'min': 1200.0, 'max': 3100.0}, {'current': 1226.875, 'min': 1200.0, 'max': 3100.0}, {'current': 2900.828, 'min': 1200.0, 'max': 3100.0}, {'current': 1211.335, 'min': 1200.0, 'max': 3100.0}, {'current': 2909.765, 'min': 1200.0, 'max': 3100.0}, {'current': 1200.062, 'min': 1200.0, 'max': 3100.0}, {'current': 3000.156, 'min': 1200.0, 'max': 3100.0}, {'current': 1208.796, 'min': 1200.0, 'max': 3100.0}, {'current': 3067.593, 'min': 1200.0, 'max': 3100.0}, {'current': 1213.671, 'min': 1200.0, 'max': 3100.0}, {'current': 2925.812, 'min': 1200.0, 'max': 3100.0}, {'current': 1209.203, 'min': 1200.0, 'max': 3100.0}, {'current': 2903.976, 'min': 1200.0, 'max': 3100.0}, {'current': 1199.96, 'min': 1200.0, 'max': 3100.0}, {'current': 2908.75, 'min': 1200.0, 'max': 3100.0}, {'current': 1210.523, 'min': 1200.0, 'max': 3100.0}, {'current': 2946.734, 'min': 1200.0, 'max': 3100.0}, {'current': 1205.75, 'min': 1200.0, 'max': 3100.0}], 'disk': {'/': {'total': 15.623897552490234, 'used': 6.485786437988281}}, 'gpu': 'NVIDIA A100-PCIE-40GB', 'gpu_count': 2, 'gpu_devices': [{'name': 'NVIDIA A100-PCIE-40GB', 'memory_total': 42949672960}, {'name': 'NVIDIA A100-PCIE-40GB', 'memory_total': 42949672960}], 'memory': {'total': 62.711788177490234}}
2025-03-03 14:28:08,643 INFO    HandlerThread:30102 [system_monitor.py:probe():224] Finished collecting system info
2025-03-03 14:28:08,643 INFO    HandlerThread:30102 [system_monitor.py:probe():227] Publishing system info
2025-03-03 14:28:08,645 INFO    HandlerThread:30102 [system_monitor.py:probe():229] Finished publishing system info
2025-03-03 14:28:08,653 DEBUG   SenderThread:30102 [sender.py:send():389] send: files
2025-03-03 14:28:08,653 INFO    SenderThread:30102 [sender.py:_save_file():1423] saving file wandb-metadata.json with policy now
2025-03-03 14:28:08,867 DEBUG   HandlerThread:30102 [handler.py:handle_request():158] handle_request: python_packages
2025-03-03 14:28:08,868 DEBUG   SenderThread:30102 [sender.py:send_request():416] send_request: python_packages
2025-03-03 14:28:08,869 DEBUG   HandlerThread:30102 [handler.py:handle_request():158] handle_request: stop_status
2025-03-03 14:28:08,870 DEBUG   SenderThread:30102 [sender.py:send_request():416] send_request: stop_status
2025-03-03 14:28:08,880 DEBUG   HandlerThread:30102 [handler.py:handle_request():158] handle_request: internal_messages
2025-03-03 14:28:08,911 ERROR   wandb-upload_0:30102 [internal_api.py:execute():358] 404 response executing GraphQL.
2025-03-03 14:28:08,912 ERROR   wandb-upload_0:30102 [internal_api.py:execute():359] {"errors":[{"message":"run Covariance_Estimation/5fy0mcge not found during createRunFiles","path":["createRunFiles"]}],"data":{"createRunFiles":null}}
2025-03-03 14:28:08,912 ERROR   Thread-11 :30102 [step_upload.py:_handle_event():144] Failed to upload file: /tmp/tmpejbj0c80wandb/6rz15g3n-wandb-metadata.json
Traceback (most recent call last):
  File "/share/nas2_3/adey/.venv/lib/python3.9/site-packages/wandb/sdk/lib/retry.py", line 131, in __call__
    result = self._call_fn(*args, **kwargs)
  File "/share/nas2_3/adey/.venv/lib/python3.9/site-packages/wandb/sdk/internal/internal_api.py", line 354, in execute
    return self.client.execute(*args, **kwargs)  # type: ignore
  File "/share/nas2_3/adey/.venv/lib/python3.9/site-packages/wandb/vendor/gql-0.2.0/wandb_gql/client.py", line 52, in execute
    result = self._get_result(document, *args, **kwargs)
  File "/share/nas2_3/adey/.venv/lib/python3.9/site-packages/wandb/vendor/gql-0.2.0/wandb_gql/client.py", line 60, in _get_result
    return self.transport.execute(document, *args, **kwargs)
  File "/share/nas2_3/adey/.venv/lib/python3.9/site-packages/wandb/sdk/lib/gql_request.py", line 59, in execute
    request.raise_for_status()
  File "/share/nas2_3/adey/.venv/lib/python3.9/site-packages/requests/models.py", line 1024, in raise_for_status
    raise HTTPError(http_error_msg, response=self)
requests.exceptions.HTTPError: 404 Client Error: Not Found for url: https://api.wandb.ai/graphql

During handling of the above exception, another exception occurred:

Traceback (most recent call last):
  File "/share/apps/python396/lib/python3.9/concurrent/futures/thread.py", line 52, in run
    result = self.fn(*self.args, **self.kwargs)
  File "/share/nas2_3/adey/.venv/lib/python3.9/site-packages/wandb/filesync/step_upload.py", line 223, in run_and_notify
    self._do_upload(event)
  File "/share/nas2_3/adey/.venv/lib/python3.9/site-packages/wandb/filesync/step_upload.py", line 243, in _do_upload
    job.run()
  File "/share/nas2_3/adey/.venv/lib/python3.9/site-packages/wandb/filesync/upload_job.py", line 56, in run
    self.push()
  File "/share/nas2_3/adey/.venv/lib/python3.9/site-packages/wandb/filesync/upload_job.py", line 105, in push
    _, upload_headers, result = self._api.upload_urls(project, [self.save_name])
  File "/share/nas2_3/adey/.venv/lib/python3.9/site-packages/wandb/apis/normalize.py", line 73, in wrapper
    raise err
  File "/share/nas2_3/adey/.venv/lib/python3.9/site-packages/wandb/apis/normalize.py", line 41, in wrapper
    return func(*args, **kwargs)
  File "/share/nas2_3/adey/.venv/lib/python3.9/site-packages/wandb/sdk/internal/internal_api.py", line 2578, in upload_urls
    query_result = self.gql(
  File "/share/nas2_3/adey/.venv/lib/python3.9/site-packages/wandb/sdk/internal/internal_api.py", line 326, in gql
    ret = self._retry_gql(
  File "/share/nas2_3/adey/.venv/lib/python3.9/site-packages/wandb/sdk/lib/retry.py", line 147, in __call__
    retry_timedelta_triggered = check_retry_fn(e)
  File "/share/nas2_3/adey/.venv/lib/python3.9/site-packages/wandb/util.py", line 910, in no_retry_auth
    raise CommError(
wandb.errors.errors.CommError: It appears that you do not have permission to access the requested resource. Please reach out to the project owner to grant you access. If you have the correct permissions, verify that there are no issues with your networking setup.(Error 404: Not Found)
2025-03-03 14:28:09,161 DEBUG   SenderThread:30102 [sender.py:send():389] send: telemetry
2025-03-03 14:28:09,491 INFO    Thread-12 :30102 [dir_watcher.py:_on_file_created():271] file/dir created: /share/nas2_3/adey/github/Neural-Compression-for-Radio-Astronomy/vqvae/wandb/run-20250303_142807-5fy0mcge/files/wandb-metadata.json
2025-03-03 14:28:09,491 INFO    Thread-12 :30102 [dir_watcher.py:_on_file_created():271] file/dir created: /share/nas2_3/adey/github/Neural-Compression-for-Radio-Astronomy/vqvae/wandb/run-20250303_142807-5fy0mcge/files/requirements.txt
2025-03-03 14:28:13,163 DEBUG   HandlerThread:30102 [handler.py:handle_request():158] handle_request: status_report
2025-03-03 14:28:18,878 DEBUG   HandlerThread:30102 [handler.py:handle_request():158] handle_request: status_report
2025-03-03 14:28:18,878 DEBUG   HandlerThread:30102 [handler.py:handle_request():158] handle_request: internal_messages
2025-03-03 14:28:23,869 DEBUG   HandlerThread:30102 [handler.py:handle_request():158] handle_request: stop_status
2025-03-03 14:28:23,870 DEBUG   SenderThread:30102 [sender.py:send_request():416] send_request: stop_status
2025-03-03 14:28:24,074 DEBUG   HandlerThread:30102 [handler.py:handle_request():158] handle_request: status_report
2025-03-03 14:28:28,878 DEBUG   HandlerThread:30102 [handler.py:handle_request():158] handle_request: internal_messages
2025-03-03 14:28:29,877 DEBUG   HandlerThread:30102 [handler.py:handle_request():158] handle_request: status_report
2025-03-03 14:28:34,878 DEBUG   HandlerThread:30102 [handler.py:handle_request():158] handle_request: status_report
2025-03-03 14:28:38,869 DEBUG   HandlerThread:30102 [handler.py:handle_request():158] handle_request: stop_status
2025-03-03 14:28:38,870 DEBUG   SenderThread:30102 [sender.py:send_request():416] send_request: stop_status
2025-03-03 14:28:38,909 DEBUG   HandlerThread:30102 [handler.py:handle_request():158] handle_request: internal_messages
2025-03-03 14:28:40,131 DEBUG   HandlerThread:30102 [handler.py:handle_request():158] handle_request: status_report
2025-03-03 14:28:40,258 ERROR   SenderThread:30102 [internal_api.py:execute():358] 409 response executing GraphQL.
2025-03-03 14:28:40,259 ERROR   SenderThread:30102 [internal_api.py:execute():359] {"errors":[{"message":"run 5fy0mcge was previously created and deleted; try a new run name","path":["upsertBucket"]}],"data":{"upsertBucket":null}}
2025-03-03 14:28:41,484 ERROR   SenderThread:30102 [internal_api.py:execute():358] 409 response executing GraphQL.
2025-03-03 14:28:41,485 ERROR   SenderThread:30102 [internal_api.py:execute():359] {"errors":[{"message":"run 5fy0mcge was previously created and deleted; try a new run name","path":["upsertBucket"]}],"data":{"upsertBucket":null}}
2025-03-03 14:28:43,854 ERROR   SenderThread:30102 [internal_api.py:execute():358] 409 response executing GraphQL.
2025-03-03 14:28:43,854 ERROR   SenderThread:30102 [internal_api.py:execute():359] {"errors":[{"message":"run 5fy0mcge was previously created and deleted; try a new run name","path":["upsertBucket"]}],"data":{"upsertBucket":null}}
2025-03-03 14:28:43,854 INFO    SenderThread:30102 [retry.py:__call__():172] Retry attempt failed:
Traceback (most recent call last):
  File "/share/nas2_3/adey/.venv/lib/python3.9/site-packages/wandb/sdk/lib/retry.py", line 131, in __call__
    result = self._call_fn(*args, **kwargs)
  File "/share/nas2_3/adey/.venv/lib/python3.9/site-packages/wandb/sdk/internal/internal_api.py", line 354, in execute
    return self.client.execute(*args, **kwargs)  # type: ignore
  File "/share/nas2_3/adey/.venv/lib/python3.9/site-packages/wandb/vendor/gql-0.2.0/wandb_gql/client.py", line 52, in execute
    result = self._get_result(document, *args, **kwargs)
  File "/share/nas2_3/adey/.venv/lib/python3.9/site-packages/wandb/vendor/gql-0.2.0/wandb_gql/client.py", line 60, in _get_result
    return self.transport.execute(document, *args, **kwargs)
  File "/share/nas2_3/adey/.venv/lib/python3.9/site-packages/wandb/sdk/lib/gql_request.py", line 59, in execute
    request.raise_for_status()
  File "/share/nas2_3/adey/.venv/lib/python3.9/site-packages/requests/models.py", line 1024, in raise_for_status
    raise HTTPError(http_error_msg, response=self)
requests.exceptions.HTTPError: 409 Client Error: Conflict for url: https://api.wandb.ai/graphql
2025-03-03 14:28:48,157 ERROR   SenderThread:30102 [internal_api.py:execute():358] 409 response executing GraphQL.
2025-03-03 14:28:48,157 ERROR   SenderThread:30102 [internal_api.py:execute():359] {"errors":[{"message":"run 5fy0mcge was previously created and deleted; try a new run name","path":["upsertBucket"]}],"data":{"upsertBucket":null}}
2025-03-03 14:28:48,878 DEBUG   HandlerThread:30102 [handler.py:handle_request():158] handle_request: keepalive
2025-03-03 14:28:48,878 DEBUG   HandlerThread:30102 [handler.py:handle_request():158] handle_request: internal_messages
2025-03-03 14:28:53,870 DEBUG   HandlerThread:30102 [handler.py:handle_request():158] handle_request: stop_status
2025-03-03 14:28:57,777 ERROR   SenderThread:30102 [internal_api.py:execute():358] 409 response executing GraphQL.
2025-03-03 14:28:57,777 ERROR   SenderThread:30102 [internal_api.py:execute():359] {"errors":[{"message":"run 5fy0mcge was previously created and deleted; try a new run name","path":["upsertBucket"]}],"data":{"upsertBucket":null}}
2025-03-03 14:28:58,895 DEBUG   HandlerThread:30102 [handler.py:handle_request():158] handle_request: internal_messages
2025-03-03 14:29:04,220 DEBUG   HandlerThread:30102 [handler.py:handle_request():158] handle_request: keepalive
2025-03-03 14:29:05,489 DEBUG   HandlerThread:30102 [handler.py:handle_request():158] handle_request: poll_exit
2025-03-03 14:29:08,576 DEBUG   SystemMonitor:30102 [system_monitor.py:_start():172] Starting system metrics aggregation loop
2025-03-03 14:29:10,491 DEBUG   HandlerThread:30102 [handler.py:handle_request():158] handle_request: keepalive
2025-03-03 14:29:15,493 DEBUG   HandlerThread:30102 [handler.py:handle_request():158] handle_request: keepalive
2025-03-03 14:29:16,695 ERROR   SenderThread:30102 [internal_api.py:execute():358] 409 response executing GraphQL.
2025-03-03 14:29:16,696 ERROR   SenderThread:30102 [internal_api.py:execute():359] {"errors":[{"message":"run 5fy0mcge was previously created and deleted; try a new run name","path":["upsertBucket"]}],"data":{"upsertBucket":null}}
2025-03-03 14:29:20,494 DEBUG   HandlerThread:30102 [handler.py:handle_request():158] handle_request: keepalive
2025-03-03 14:29:25,496 DEBUG   HandlerThread:30102 [handler.py:handle_request():158] handle_request: keepalive
2025-03-03 14:29:30,497 DEBUG   HandlerThread:30102 [handler.py:handle_request():158] handle_request: keepalive
2025-03-03 14:29:35,499 DEBUG   HandlerThread:30102 [handler.py:handle_request():158] handle_request: keepalive
2025-03-03 14:29:40,500 DEBUG   HandlerThread:30102 [handler.py:handle_request():158] handle_request: keepalive
2025-03-03 14:29:45,501 DEBUG   HandlerThread:30102 [handler.py:handle_request():158] handle_request: keepalive
2025-03-03 14:29:50,503 DEBUG   HandlerThread:30102 [handler.py:handle_request():158] handle_request: keepalive
2025-03-03 14:29:54,372 ERROR   SenderThread:30102 [internal_api.py:execute():358] 409 response executing GraphQL.
2025-03-03 14:29:54,373 ERROR   SenderThread:30102 [internal_api.py:execute():359] {"errors":[{"message":"run 5fy0mcge was previously created and deleted; try a new run name","path":["upsertBucket"]}],"data":{"upsertBucket":null}}
2025-03-03 14:29:55,504 DEBUG   HandlerThread:30102 [handler.py:handle_request():158] handle_request: keepalive
2025-03-03 14:30:00,506 DEBUG   HandlerThread:30102 [handler.py:handle_request():158] handle_request: keepalive
2025-03-03 14:30:05,507 DEBUG   HandlerThread:30102 [handler.py:handle_request():158] handle_request: keepalive
2025-03-03 14:30:10,508 DEBUG   HandlerThread:30102 [handler.py:handle_request():158] handle_request: keepalive
2025-03-03 14:30:15,510 DEBUG   HandlerThread:30102 [handler.py:handle_request():158] handle_request: keepalive
2025-03-03 14:30:20,511 DEBUG   HandlerThread:30102 [handler.py:handle_request():158] handle_request: keepalive
2025-03-03 14:30:25,512 DEBUG   HandlerThread:30102 [handler.py:handle_request():158] handle_request: keepalive
2025-03-03 14:30:30,514 DEBUG   HandlerThread:30102 [handler.py:handle_request():158] handle_request: keepalive
2025-03-03 14:30:35,515 DEBUG   HandlerThread:30102 [handler.py:handle_request():158] handle_request: keepalive
2025-03-03 14:30:40,518 DEBUG   HandlerThread:30102 [handler.py:handle_request():158] handle_request: keepalive
2025-03-03 14:30:40,698 INFO    cpu       :30102 [interfaces.py:monitor():138] Process cpu has exited.
2025-03-03 14:30:40,698 DEBUG   SystemMonitor:30102 [system_monitor.py:_start():179] Finished system metrics aggregation loop
2025-03-03 14:30:40,698 DEBUG   SystemMonitor:30102 [system_monitor.py:_start():183] Publishing last batch of metrics
2025-03-03 14:30:41,200 WARNING StreamThr :30102 [internal.py:is_dead():413] Internal process exiting, parent pid 30081 disappeared
2025-03-03 14:30:41,200 ERROR   StreamThr :30102 [internal.py:wandb_internal():151] Internal process shutdown.
2025-03-03 14:30:41,705 INFO    HandlerThread:30102 [handler.py:finish():874] shutting down handler
2025-03-03 14:30:41,705 INFO    HandlerThread:30102 [system_monitor.py:finish():203] Stopping system monitor
2025-03-03 14:30:41,705 INFO    HandlerThread:30102 [interfaces.py:finish():200] Joined cpu monitor
2025-03-03 14:30:41,706 INFO    HandlerThread:30102 [interfaces.py:finish():200] Joined disk monitor
2025-03-03 14:30:41,706 INFO    HandlerThread:30102 [interfaces.py:finish():200] Joined gpu monitor
2025-03-03 14:30:41,707 INFO    HandlerThread:30102 [interfaces.py:finish():200] Joined memory monitor
2025-03-03 14:30:41,707 INFO    HandlerThread:30102 [interfaces.py:finish():200] Joined network monitor
2025-03-03 14:30:41,708 INFO    WriterThread:30102 [datastore.py:close():296] close: /share/nas2_3/adey/github/Neural-Compression-for-Radio-Astronomy/vqvae/wandb/run-20250303_142807-5fy0mcge/run-5fy0mcge.wandb
2025-03-03 14:31:12,664 ERROR   SenderThread:30102 [internal_api.py:execute():358] 409 response executing GraphQL.
2025-03-03 14:31:12,664 ERROR   SenderThread:30102 [internal_api.py:execute():359] {"errors":[{"message":"run 5fy0mcge was previously created and deleted; try a new run name","path":["upsertBucket"]}],"data":{"upsertBucket":null}}
2025-03-03 14:31:12,666 ERROR   StreamThr :30102 [internal.py:wandb_internal():173] Thread SenderThread:
Traceback (most recent call last):
  File "/share/nas2_3/adey/.venv/lib/python3.9/site-packages/wandb/apis/normalize.py", line 41, in wrapper
    return func(*args, **kwargs)
  File "/share/nas2_3/adey/.venv/lib/python3.9/site-packages/wandb/sdk/internal/internal_api.py", line 2302, in upsert_run
    response = self.gql(
  File "/share/nas2_3/adey/.venv/lib/python3.9/site-packages/wandb/sdk/internal/internal_api.py", line 326, in gql
    ret = self._retry_gql(
  File "/share/nas2_3/adey/.venv/lib/python3.9/site-packages/wandb/sdk/lib/retry.py", line 131, in __call__
    result = self._call_fn(*args, **kwargs)
  File "/share/nas2_3/adey/.venv/lib/python3.9/site-packages/wandb/sdk/internal/internal_api.py", line 354, in execute
    return self.client.execute(*args, **kwargs)  # type: ignore
  File "/share/nas2_3/adey/.venv/lib/python3.9/site-packages/wandb/vendor/gql-0.2.0/wandb_gql/client.py", line 52, in execute
    result = self._get_result(document, *args, **kwargs)
  File "/share/nas2_3/adey/.venv/lib/python3.9/site-packages/wandb/vendor/gql-0.2.0/wandb_gql/client.py", line 60, in _get_result
    return self.transport.execute(document, *args, **kwargs)
  File "/share/nas2_3/adey/.venv/lib/python3.9/site-packages/wandb/sdk/lib/gql_request.py", line 59, in execute
    request.raise_for_status()
  File "/share/nas2_3/adey/.venv/lib/python3.9/site-packages/requests/models.py", line 1024, in raise_for_status
    raise HTTPError(http_error_msg, response=self)
requests.exceptions.HTTPError: 409 Client Error: Conflict for url: https://api.wandb.ai/graphql

During handling of the above exception, another exception occurred:

Traceback (most recent call last):
  File "/share/nas2_3/adey/.venv/lib/python3.9/site-packages/wandb/sdk/internal/internal_util.py", line 48, in run
    self._run()
  File "/share/nas2_3/adey/.venv/lib/python3.9/site-packages/wandb/sdk/internal/internal_util.py", line 92, in _run
    self._debounce()
  File "/share/nas2_3/adey/.venv/lib/python3.9/site-packages/wandb/sdk/internal/internal.py", line 333, in _debounce
    self._sm.debounce()
  File "/share/nas2_3/adey/.venv/lib/python3.9/site-packages/wandb/sdk/internal/sender.py", line 528, in debounce
    self._maybe_update_config(always=final)
  File "/share/nas2_3/adey/.venv/lib/python3.9/site-packages/wandb/sdk/internal/sender.py", line 505, in _maybe_update_config
    self._debounce_config()
  File "/share/nas2_3/adey/.venv/lib/python3.9/site-packages/wandb/sdk/internal/sender.py", line 534, in _debounce_config
    self._api.upsert_run(
  File "/share/nas2_3/adey/.venv/lib/python3.9/site-packages/wandb/apis/normalize.py", line 51, in wrapper
    raise CommError(message, error)
wandb.errors.errors.CommError: run 5fy0mcge was previously created and deleted; try a new run name (Error 409: Conflict)
